<?xml version="1.0" ?>
<robot xmlns:xacro="http://ros.org/wiki/xacro">
  <!-- <xacro:include filename="$(find tb3_mobile_manipulation_description)/urdf/common_properties.xacro"/> -->
  <xacro:include filename="$(find tb3_mobile_manipulation_description)/urdf/tb3_mobile_manipulation.base.gazebo.xacro"/>

  <xacro:macro name="tb3_base" params="parent">
    <joint name="tb3_base_joint" type="fixed">
      <parent link="${parent}"/>
      <child link="tb3_base_link" />
      <origin xyz="0 0 0" rpy="0 0 0"/>
    </joint>
    
    <link name="tb3_base_link">
      <visual>
        <origin xyz="-0.064 0 0.0" rpy="0 0 0"/>
        <geometry>
          <mesh filename="package://tb3_mobile_manipulation_description/meshes/bases/waffle_base_for_mobile_manipulation.stl" scale="0.001 0.001 0.001"/>
        </geometry>
        <material name="light_black"/>
      </visual>
    
      <collision>
        <origin xyz="-0.064 0 0.047" rpy="0 0 0"/>
        <geometry>
          <box size="0.266 0.266 0.094"/>
        </geometry>
      </collision>
    
      <inertial>
        <!-- <origin xyz="-0.064 0 0" rpy="0 0 0"/> -->
        <origin xyz="-5.8190646e-02 3.8892103e-02 6.3998774e-02" rpy="0 0 0"/>
        <mass value="2.7771056e+00"/>
        <!-- <mass value="1.7771056e+00"/> -->
        <!-- <inertia ixx="1.8257500e-01" ixy="4.9296089e-03" ixz="-1.1606178e-05" -->
                 <!-- iyy="4.8786869e-02" iyz="1.4954898e-05" -->
                 <!-- izz="3.9852748e-02" /> -->
        <inertia ixx="1" ixy="0" ixz="0"
                 iyy="1" iyz="0"
                 izz="1" />
      </inertial>
    </link>
    
    <joint name="wheel_left_joint" type="continuous">
      <parent link="base_link"/>
      <child link="wheel_left_link"/>
      <origin xyz="0.0 0.144 0.023" rpy="${-PI*0.5} 0 0"/>
      <axis xyz="0 0 1"/>
    </joint>
    
    <link name="wheel_left_link">
      <visual>
        <origin xyz="0 0 0" rpy="${PI*0.5} 0 0"/>
        <geometry>
          <mesh filename="package://tb3_mobile_manipulation_description/meshes/wheels/left_tire.stl" scale="0.001 0.001 0.001"/>
        </geometry>
        <material name="dark"/>
      </visual>
    
      <collision>
        <origin xyz="0 0 0" rpy="0 0 0"/>
        <geometry>
          <cylinder length="0.018" radius="0.033"/>
        </geometry>
      </collision>
    
      <inertial>
        <origin xyz="0 0 0" />
        <mass value="2.8498940e-02" />
        <inertia ixx="1.1175580e-05" ixy="-4.2369783e-11" ixz="-5.9381719e-09"
                 iyy="1.1192413e-05" iyz="-1.4400107e-11"
                 izz="2.0712558e-05" />
        </inertial>
    </link>
    
    <joint name="wheel_right_joint" type="continuous">
      <parent link="base_link"/>
      <child link="wheel_right_link"/>
      <origin xyz="0.0 -0.144 0.023" rpy="${-PI*0.5} 0 0"/>
      <axis xyz="0 0 1"/>
    </joint>
    
    <link name="wheel_right_link">
      <visual>
        <origin xyz="0 0 0" rpy="${PI*0.5} 0 0"/>
        <geometry>
          <mesh filename="package://tb3_mobile_manipulation_description/meshes/wheels/right_tire.stl" scale="0.001 0.001 0.001"/>
        </geometry>
        <material name="dark"/>
      </visual>
    
      <collision>
        <origin xyz="0 0.001 0" rpy="0 0 0"/>
        <geometry>
          <cylinder length="0.018" radius="0.033"/>
        </geometry>
      </collision>
    
      <inertial>
        <origin xyz="0 0 0" />
        <mass value="2.8498940e-02" />
        <inertia ixx="1.1175580e-05" ixy="-4.2369783e-11" ixz="-5.9381719e-09"
                 iyy="1.1192413e-05" iyz="-1.4400107e-11"
                 izz="2.0712558e-05" />
        </inertial>
    </link>
    
    <joint name="caster_back_right_joint" type="fixed">
      <parent link="base_link"/>
      <child link="caster_back_right_link"/>
      <origin xyz="-0.177 -0.064 -0.004" rpy="${-PI*0.5} 0 0"/>
    </joint>
    
    <link name="caster_back_right_link">
      <collision>
        <origin xyz="0 0.001 0" rpy="0 0 0"/>
        <geometry>
          <box size="0.030 0.009 0.020"/>
        </geometry>
      </collision>
    
      <inertial>
        <origin xyz="0 0 0" />
        <mass value="0.005" />
        <inertia ixx="0.001" ixy="0.0" ixz="0.0"
                 iyy="0.001" iyz="0.0"
                 izz="0.001" />
      </inertial>
    </link>
    
    <joint name="caster_back_left_joint" type="fixed">
      <parent link="base_link"/>
      <child link="caster_back_left_link"/>
      <origin xyz="-0.177 0.064 -0.004" rpy="${-PI*0.5} 0 0"/>
    </joint>
    
    <link name="caster_back_left_link">
      <collision>
        <origin xyz="0 0.001 0" rpy="0 0 0"/>
        <geometry>
          <box size="0.030 0.009 0.020"/>
        </geometry>
      </collision>
    
      <inertial>
        <origin xyz="0 0 0" />
        <mass value="0.005" />
        <inertia ixx="0.001" ixy="0.0" ixz="0.0"
                 iyy="0.001" iyz="0.0"
                 izz="0.001" />
      </inertial>
    </link>
    
    <joint name="imu_joint" type="fixed">
      <parent link="base_link"/>
      <child link="imu_link"/>
      <origin xyz="0.0 0 0.068" rpy="0 0 0"/>
    </joint>
    
    <link name="imu_link"/>
    
    <joint name="scan_joint" type="fixed">
      <parent link="base_link"/>
      <child link="base_scan"/>
      <origin xyz="-0.024 0 0.1223" rpy="0 0 0"/> 
    </joint>
    
    <link name="base_scan">
      <visual>
        <origin xyz="0 0 0.0" rpy="0 0 0"/>
        <geometry>
          <mesh filename="package://tb3_mobile_manipulation_description/meshes/sensors/lds.stl" scale="0.001 0.001 0.001"/>
        </geometry>
        <material name="dark"/>
      </visual>
    
      <collision>
        <origin xyz="0.015 0 -0.0065" rpy="0 0 0"/>
        <geometry>
          <cylinder length="0.0315" radius="0.045"/>
        </geometry>
      </collision>
    
      <inertial>
        <mass value="0.114" />
        <origin xyz="0 0 0" />
        <inertia ixx="0.001" ixy="0.0" ixz="0.0"
                 iyy="0.001" iyz="0.0"
                 izz="0.001" />
      </inertial>
    </link>
    
    <joint name="camera_joint" type="fixed">
      <origin xyz="0.093724 0.0175 0.1005" rpy="0 0 0"/>
      <parent link="base_link"/>
      <child link="camera_link"/>
    </joint>
    
    <link name="camera_link">
      <collision>
        <origin xyz="-0.012 -0.017 0.0" rpy="0 0 0"/>
        <geometry>
          <box size="0.024 0.09 0.025"/>
        </geometry>
      </collision>
    </link>
        
    <joint name="camera_rgb_joint" type="fixed">
      <origin xyz="0 0 0" rpy="0 0 0"/>
      <parent link="camera_link"/>
      <child link="camera_rgb_frame"/>
    </joint>
    <link name="camera_rgb_frame"/>
    
    <joint name="camera_rgb_optical_joint" type="fixed">
      <origin xyz="0 0 0" rpy="${-PI*0.5} 0 ${-PI*0.5}"/>
      <parent link="camera_rgb_frame"/>
      <child link="camera_rgb_optical_frame"/>
    </joint>
    <link name="camera_rgb_optical_frame"/>
    
  </xacro:macro>

</robot>
